[2024-10-17 10:10:01,933] ERROR in app: Exception on /manage_events [GET]
Traceback (most recent call last):
  File "/home/runner/EventHighlightCalendar/.pythonlibs/lib/python3.11/site-packages/flask/app.py", line 2190, in wsgi_app
    response = self.full_dispatch_request()
               ^^^^^^^^^^^^^^^^^^^^^^^^^^^^
  File "/home/runner/EventHighlightCalendar/.pythonlibs/lib/python3.11/site-packages/flask/app.py", line 1486, in full_dispatch_request
    rv = self.handle_user_exception(e)
         ^^^^^^^^^^^^^^^^^^^^^^^^^^^^^
  File "/home/runner/EventHighlightCalendar/.pythonlibs/lib/python3.11/site-packages/flask/app.py", line 1484, in full_dispatch_request
    rv = self.dispatch_request()
         ^^^^^^^^^^^^^^^^^^^^^^^
  File "/home/runner/EventHighlightCalendar/.pythonlibs/lib/python3.11/site-packages/flask/app.py", line 1469, in dispatch_request
    return self.ensure_sync(self.view_functions[rule.endpoint])(**view_args)
           ^^^^^^^^^^^^^^^^^^^^^^^^^^^^^^^^^^^^^^^^^^^^^^^^^^^^^^^^^^^^^^^^^
  File "/home/runner/EventHighlightCalendar/routes.py", line 69, in manage_events
    return render_template('manage_events.html', events=events)
           ^^^^^^^^^^^^^^^^^^^^^^^^^^^^^^^^^^^^^^^^^^^^^^^^^^^^
  File "/home/runner/EventHighlightCalendar/.pythonlibs/lib/python3.11/site-packages/flask/templating.py", line 151, in render_template
    return _render(app, template, context)
           ^^^^^^^^^^^^^^^^^^^^^^^^^^^^^^^
  File "/home/runner/EventHighlightCalendar/.pythonlibs/lib/python3.11/site-packages/flask/templating.py", line 132, in _render
    rv = template.render(context)
         ^^^^^^^^^^^^^^^^^^^^^^^^
  File "/home/runner/EventHighlightCalendar/.pythonlibs/lib/python3.11/site-packages/jinja2/environment.py", line 1304, in render
    self.environment.handle_exception()
  File "/home/runner/EventHighlightCalendar/.pythonlibs/lib/python3.11/site-packages/jinja2/environment.py", line 939, in handle_exception
    raise rewrite_traceback_stack(source=source)
  File "/home/runner/EventHighlightCalendar/templates/manage_events.html", line 1, in top-level template code
    {% extends "base.html" %}
  File "/home/runner/EventHighlightCalendar/templates/base.html", line 38, in top-level template code
    {% block content %}{% endblock %}
    ^^^^^^^^^^^^^^^^^^^^^^^^^
  File "/home/runner/EventHighlightCalendar/templates/manage_events.html", line 7, in block 'content'
    <form id="bulk-delete-form" method="POST" action="{{ url_for('bulk_delete_events') }}">
    ^^^^^^^^^^^^^^^^^^^^^^^^^
  File "/home/runner/EventHighlightCalendar/.pythonlibs/lib/python3.11/site-packages/flask/app.py", line 1697, in url_for
    return self.handle_url_build_error(error, endpoint, values)
           ^^^^^^^^^^^^^^^^^^^^^^^^^^^^^^^^^^^^^^^^^^^^^^^^^^^^
  File "/home/runner/EventHighlightCalendar/.pythonlibs/lib/python3.11/site-packages/flask/app.py", line 1686, in url_for
    rv = url_adapter.build(  # type: ignore[union-attr]
         ^^^^^^^^^^^^^^^^^^^^^^^^^^^^^^^^^^^^^^^^^^^^^^
  File "/home/runner/EventHighlightCalendar/.pythonlibs/lib/python3.11/site-packages/werkzeug/routing/map.py", line 950, in build
    raise BuildError(endpoint, values, method, self)
werkzeug.routing.exceptions.BuildError: Could not build url for endpoint 'bulk_delete_events'. Did you mean 'get_events' instead?
172.31.196.78 - - [17/Oct/2024 10:10:01] "GET /manage_events HTTP/1.1" 500 -
^C